2023-11-21 19:11:12,031 INFO    StreamThr :24097 [internal.py:wandb_internal():86] W&B internal server running at pid: 24097, started at: 2023-11-21 19:11:12.031204
2023-11-21 19:11:12,034 DEBUG   HandlerThread:24097 [handler.py:handle_request():146] handle_request: status
2023-11-21 19:11:12,038 INFO    WriterThread:24097 [datastore.py:open_for_write():85] open: /home/mitul/Downloads/penalty-shot-project/wandb/run-20231121_191112-l6tp1xc1/run-l6tp1xc1.wandb
2023-11-21 19:11:12,038 DEBUG   SenderThread:24097 [sender.py:send():380] send: header
2023-11-21 19:11:12,051 DEBUG   SenderThread:24097 [sender.py:send():380] send: run
2023-11-21 19:11:12,053 INFO    SenderThread:24097 [sender.py:_maybe_setup_resume():759] checking resume status for ramanujan123/ds251_project/l6tp1xc1
2023-11-21 19:11:15,722 INFO    SenderThread:24097 [retry.py:__call__():172] Retry attempt failed:
Traceback (most recent call last):
  File "/home/mitul/Downloads/penalty-shot-project/venv/lib/python3.8/site-packages/urllib3/connection.py", line 203, in _new_conn
    sock = connection.create_connection(
  File "/home/mitul/Downloads/penalty-shot-project/venv/lib/python3.8/site-packages/urllib3/util/connection.py", line 60, in create_connection
    for res in socket.getaddrinfo(host, port, family, socket.SOCK_STREAM):
  File "/usr/local/lib/python3.8/socket.py", line 918, in getaddrinfo
    for res in _socket.getaddrinfo(host, port, family, type, proto, flags):
socket.gaierror: [Errno -3] Temporary failure in name resolution

The above exception was the direct cause of the following exception:

Traceback (most recent call last):
  File "/home/mitul/Downloads/penalty-shot-project/venv/lib/python3.8/site-packages/urllib3/connectionpool.py", line 790, in urlopen
    response = self._make_request(
  File "/home/mitul/Downloads/penalty-shot-project/venv/lib/python3.8/site-packages/urllib3/connectionpool.py", line 491, in _make_request
    raise new_e
  File "/home/mitul/Downloads/penalty-shot-project/venv/lib/python3.8/site-packages/urllib3/connectionpool.py", line 467, in _make_request
    self._validate_conn(conn)
  File "/home/mitul/Downloads/penalty-shot-project/venv/lib/python3.8/site-packages/urllib3/connectionpool.py", line 1096, in _validate_conn
    conn.connect()
  File "/home/mitul/Downloads/penalty-shot-project/venv/lib/python3.8/site-packages/urllib3/connection.py", line 611, in connect
    self.sock = sock = self._new_conn()
  File "/home/mitul/Downloads/penalty-shot-project/venv/lib/python3.8/site-packages/urllib3/connection.py", line 210, in _new_conn
    raise NameResolutionError(self.host, self, e) from e
urllib3.exceptions.NameResolutionError: <urllib3.connection.HTTPSConnection object at 0x7fe07231a040>: Failed to resolve 'api.wandb.ai' ([Errno -3] Temporary failure in name resolution)

The above exception was the direct cause of the following exception:

Traceback (most recent call last):
  File "/home/mitul/Downloads/penalty-shot-project/venv/lib/python3.8/site-packages/requests/adapters.py", line 486, in send
    resp = conn.urlopen(
  File "/home/mitul/Downloads/penalty-shot-project/venv/lib/python3.8/site-packages/urllib3/connectionpool.py", line 844, in urlopen
    retries = retries.increment(
  File "/home/mitul/Downloads/penalty-shot-project/venv/lib/python3.8/site-packages/urllib3/util/retry.py", line 515, in increment
    raise MaxRetryError(_pool, url, reason) from reason  # type: ignore[arg-type]
urllib3.exceptions.MaxRetryError: HTTPSConnectionPool(host='api.wandb.ai', port=443): Max retries exceeded with url: /graphql (Caused by NameResolutionError("<urllib3.connection.HTTPSConnection object at 0x7fe07231a040>: Failed to resolve 'api.wandb.ai' ([Errno -3] Temporary failure in name resolution)"))

During handling of the above exception, another exception occurred:

Traceback (most recent call last):
  File "/home/mitul/Downloads/penalty-shot-project/venv/lib/python3.8/site-packages/wandb/sdk/lib/retry.py", line 131, in __call__
    result = self._call_fn(*args, **kwargs)
  File "/home/mitul/Downloads/penalty-shot-project/venv/lib/python3.8/site-packages/wandb/sdk/internal/internal_api.py", line 366, in execute
    return self.client.execute(*args, **kwargs)  # type: ignore
  File "/home/mitul/Downloads/penalty-shot-project/venv/lib/python3.8/site-packages/wandb/vendor/gql-0.2.0/wandb_gql/client.py", line 52, in execute
    result = self._get_result(document, *args, **kwargs)
  File "/home/mitul/Downloads/penalty-shot-project/venv/lib/python3.8/site-packages/wandb/vendor/gql-0.2.0/wandb_gql/client.py", line 60, in _get_result
    return self.transport.execute(document, *args, **kwargs)
  File "/home/mitul/Downloads/penalty-shot-project/venv/lib/python3.8/site-packages/wandb/sdk/lib/gql_request.py", line 58, in execute
    request = self.session.post(self.url, **post_args)
  File "/home/mitul/Downloads/penalty-shot-project/venv/lib/python3.8/site-packages/requests/sessions.py", line 637, in post
    return self.request("POST", url, data=data, json=json, **kwargs)
  File "/home/mitul/Downloads/penalty-shot-project/venv/lib/python3.8/site-packages/requests/sessions.py", line 589, in request
    resp = self.send(prep, **send_kwargs)
  File "/home/mitul/Downloads/penalty-shot-project/venv/lib/python3.8/site-packages/requests/sessions.py", line 703, in send
    r = adapter.send(request, **kwargs)
  File "/home/mitul/Downloads/penalty-shot-project/venv/lib/python3.8/site-packages/requests/adapters.py", line 519, in send
    raise ConnectionError(e, request=request)
requests.exceptions.ConnectionError: HTTPSConnectionPool(host='api.wandb.ai', port=443): Max retries exceeded with url: /graphql (Caused by NameResolutionError("<urllib3.connection.HTTPSConnection object at 0x7fe07231a040>: Failed to resolve 'api.wandb.ai' ([Errno -3] Temporary failure in name resolution)"))
2023-11-21 19:11:17,053 DEBUG   HandlerThread:24097 [handler.py:handle_request():146] handle_request: keepalive
2023-11-21 19:11:18,396 DEBUG   HandlerThread:24097 [handler.py:handle_request():146] handle_request: shutdown
2023-11-21 19:11:18,396 INFO    HandlerThread:24097 [handler.py:finish():866] shutting down handler
2023-11-21 19:11:19,053 INFO    WriterThread:24097 [datastore.py:close():294] close: /home/mitul/Downloads/penalty-shot-project/wandb/run-20231121_191112-l6tp1xc1/run-l6tp1xc1.wandb
2023-11-21 19:11:48,626 ERROR   SenderThread:24097 [internal_api.py:execute():370] 404 response executing GraphQL.
2023-11-21 19:11:48,626 ERROR   SenderThread:24097 [internal_api.py:execute():371] {"errors":[{"message":"entity ramanujan123 not found during upsertBucket","path":["upsertBucket"]}],"data":{"upsertBucket":null}}
2023-11-21 19:11:48,627 ERROR   SenderThread:24097 [sender.py:send_run():979] It appears that you do not have permission to access the requested resource. Please reach out to the project owner to grant you access. If you have the correct permissions, verify that there are no issues with your networking setup.(Error 404: Not Found)
Traceback (most recent call last):
  File "/home/mitul/Downloads/penalty-shot-project/venv/lib/python3.8/site-packages/wandb/sdk/lib/retry.py", line 131, in __call__
    result = self._call_fn(*args, **kwargs)
  File "/home/mitul/Downloads/penalty-shot-project/venv/lib/python3.8/site-packages/wandb/sdk/internal/internal_api.py", line 366, in execute
    return self.client.execute(*args, **kwargs)  # type: ignore
  File "/home/mitul/Downloads/penalty-shot-project/venv/lib/python3.8/site-packages/wandb/vendor/gql-0.2.0/wandb_gql/client.py", line 52, in execute
    result = self._get_result(document, *args, **kwargs)
  File "/home/mitul/Downloads/penalty-shot-project/venv/lib/python3.8/site-packages/wandb/vendor/gql-0.2.0/wandb_gql/client.py", line 60, in _get_result
    return self.transport.execute(document, *args, **kwargs)
  File "/home/mitul/Downloads/penalty-shot-project/venv/lib/python3.8/site-packages/wandb/sdk/lib/gql_request.py", line 59, in execute
    request.raise_for_status()
  File "/home/mitul/Downloads/penalty-shot-project/venv/lib/python3.8/site-packages/requests/models.py", line 1021, in raise_for_status
    raise HTTPError(http_error_msg, response=self)
requests.exceptions.HTTPError: 404 Client Error: Not Found for url: https://api.wandb.ai/graphql

During handling of the above exception, another exception occurred:

Traceback (most recent call last):
  File "/home/mitul/Downloads/penalty-shot-project/venv/lib/python3.8/site-packages/wandb/sdk/internal/sender.py", line 977, in send_run
    self._init_run(run, config_value_dict)
  File "/home/mitul/Downloads/penalty-shot-project/venv/lib/python3.8/site-packages/wandb/sdk/internal/sender.py", line 1015, in _init_run
    server_run, inserted, server_messages = self._api.upsert_run(
  File "/home/mitul/Downloads/penalty-shot-project/venv/lib/python3.8/site-packages/wandb/apis/normalize.py", line 73, in wrapper
    raise err
  File "/home/mitul/Downloads/penalty-shot-project/venv/lib/python3.8/site-packages/wandb/apis/normalize.py", line 41, in wrapper
    return func(*args, **kwargs)
  File "/home/mitul/Downloads/penalty-shot-project/venv/lib/python3.8/site-packages/wandb/sdk/internal/internal_api.py", line 2008, in upsert_run
    response = self.gql(
  File "/home/mitul/Downloads/penalty-shot-project/venv/lib/python3.8/site-packages/wandb/sdk/internal/internal_api.py", line 338, in gql
    ret = self._retry_gql(
  File "/home/mitul/Downloads/penalty-shot-project/venv/lib/python3.8/site-packages/wandb/sdk/lib/retry.py", line 147, in __call__
    retry_timedelta_triggered = check_retry_fn(e)
  File "/home/mitul/Downloads/penalty-shot-project/venv/lib/python3.8/site-packages/wandb/util.py", line 965, in check_retry_fn
    return fallback_retry_fn(e)
  File "/home/mitul/Downloads/penalty-shot-project/venv/lib/python3.8/site-packages/wandb/util.py", line 907, in no_retry_auth
    raise CommError(
wandb.errors.CommError: It appears that you do not have permission to access the requested resource. Please reach out to the project owner to grant you access. If you have the correct permissions, verify that there are no issues with your networking setup.(Error 404: Not Found)
2023-11-21 19:11:48,629 INFO    SenderThread:24097 [sender.py:finish():1536] shutting down sender
