2023-11-21 19:04:37,464 INFO    StreamThr :23624 [internal.py:wandb_internal():86] W&B internal server running at pid: 23624, started at: 2023-11-21 19:04:37.464563
2023-11-21 19:04:37,466 DEBUG   HandlerThread:23624 [handler.py:handle_request():146] handle_request: status
2023-11-21 19:04:37,471 INFO    WriterThread:23624 [datastore.py:open_for_write():85] open: /home/mitul/Downloads/penalty-shot-project/wandb/run-20231121_190437-ee4dh8yt/run-ee4dh8yt.wandb
2023-11-21 19:04:37,471 DEBUG   SenderThread:23624 [sender.py:send():380] send: header
2023-11-21 19:04:37,490 DEBUG   SenderThread:23624 [sender.py:send():380] send: run
2023-11-21 19:04:37,492 INFO    SenderThread:23624 [sender.py:_maybe_setup_resume():759] checking resume status for penalty-shot-project/test-project/ee4dh8yt
2023-11-21 19:04:39,297 ERROR   SenderThread:23624 [internal_api.py:execute():370] 404 response executing GraphQL.
2023-11-21 19:04:39,297 ERROR   SenderThread:23624 [internal_api.py:execute():371] {"errors":[{"message":"project not found","path":["upsertBucket"]}],"data":{"upsertBucket":null}}
2023-11-21 19:04:39,298 ERROR   SenderThread:23624 [sender.py:send_run():979] It appears that you do not have permission to access the requested resource. Please reach out to the project owner to grant you access. If you have the correct permissions, verify that there are no issues with your networking setup.(Error 404: Not Found)
Traceback (most recent call last):
  File "/home/mitul/Downloads/penalty-shot-project/venv/lib/python3.8/site-packages/wandb/sdk/lib/retry.py", line 131, in __call__
    result = self._call_fn(*args, **kwargs)
  File "/home/mitul/Downloads/penalty-shot-project/venv/lib/python3.8/site-packages/wandb/sdk/internal/internal_api.py", line 366, in execute
    return self.client.execute(*args, **kwargs)  # type: ignore
  File "/home/mitul/Downloads/penalty-shot-project/venv/lib/python3.8/site-packages/wandb/vendor/gql-0.2.0/wandb_gql/client.py", line 52, in execute
    result = self._get_result(document, *args, **kwargs)
  File "/home/mitul/Downloads/penalty-shot-project/venv/lib/python3.8/site-packages/wandb/vendor/gql-0.2.0/wandb_gql/client.py", line 60, in _get_result
    return self.transport.execute(document, *args, **kwargs)
  File "/home/mitul/Downloads/penalty-shot-project/venv/lib/python3.8/site-packages/wandb/sdk/lib/gql_request.py", line 59, in execute
    request.raise_for_status()
  File "/home/mitul/Downloads/penalty-shot-project/venv/lib/python3.8/site-packages/requests/models.py", line 1021, in raise_for_status
    raise HTTPError(http_error_msg, response=self)
requests.exceptions.HTTPError: 404 Client Error: Not Found for url: https://api.wandb.ai/graphql

During handling of the above exception, another exception occurred:

Traceback (most recent call last):
  File "/home/mitul/Downloads/penalty-shot-project/venv/lib/python3.8/site-packages/wandb/sdk/internal/sender.py", line 977, in send_run
    self._init_run(run, config_value_dict)
  File "/home/mitul/Downloads/penalty-shot-project/venv/lib/python3.8/site-packages/wandb/sdk/internal/sender.py", line 1015, in _init_run
    server_run, inserted, server_messages = self._api.upsert_run(
  File "/home/mitul/Downloads/penalty-shot-project/venv/lib/python3.8/site-packages/wandb/apis/normalize.py", line 73, in wrapper
    raise err
  File "/home/mitul/Downloads/penalty-shot-project/venv/lib/python3.8/site-packages/wandb/apis/normalize.py", line 41, in wrapper
    return func(*args, **kwargs)
  File "/home/mitul/Downloads/penalty-shot-project/venv/lib/python3.8/site-packages/wandb/sdk/internal/internal_api.py", line 2008, in upsert_run
    response = self.gql(
  File "/home/mitul/Downloads/penalty-shot-project/venv/lib/python3.8/site-packages/wandb/sdk/internal/internal_api.py", line 338, in gql
    ret = self._retry_gql(
  File "/home/mitul/Downloads/penalty-shot-project/venv/lib/python3.8/site-packages/wandb/sdk/lib/retry.py", line 147, in __call__
    retry_timedelta_triggered = check_retry_fn(e)
  File "/home/mitul/Downloads/penalty-shot-project/venv/lib/python3.8/site-packages/wandb/util.py", line 965, in check_retry_fn
    return fallback_retry_fn(e)
  File "/home/mitul/Downloads/penalty-shot-project/venv/lib/python3.8/site-packages/wandb/util.py", line 907, in no_retry_auth
    raise CommError(
wandb.errors.CommError: It appears that you do not have permission to access the requested resource. Please reach out to the project owner to grant you access. If you have the correct permissions, verify that there are no issues with your networking setup.(Error 404: Not Found)
2023-11-21 19:04:40,015 DEBUG   HandlerThread:23624 [handler.py:handle_request():146] handle_request: shutdown
2023-11-21 19:04:40,015 INFO    HandlerThread:23624 [handler.py:finish():866] shutting down handler
2023-11-21 19:04:40,302 INFO    SenderThread:23624 [sender.py:finish():1536] shutting down sender
2023-11-21 19:04:40,491 INFO    WriterThread:23624 [datastore.py:close():294] close: /home/mitul/Downloads/penalty-shot-project/wandb/run-20231121_190437-ee4dh8yt/run-ee4dh8yt.wandb
